Workbook

Sheet CS-Estruturante
A1: Controle/Correlação | B1: Componente | C1: Riscos | D1: STRIDE LM | E1: OWASP-TOP10 | F1: On-Prem | G1: IaaS | H1: PaaS | I1: SaaS | J1: Tecnologia/Processo
A2: Obrigatorio publicar serviços na arquitetura “Hub-Spoken”, estabelecidas durante cada Landingzone, com todas as proteções | B2: Cloud Security - Estruturante | C2: Vazamento de dados | D2: STRIDE | E2: A04:2021-Insecure Design | F2: Não | G2: Sim | H2: Sim | I2: Não | J2: IPS, WAF, Firewall, TLS, API Gateway etc.
A3: A arquitetura deve seguir o modelo de segregação por funcionalidades. (Apresentação, Lógica de negócio, Persistência/Dados) | B3: Cloud Security - Estruturante | C3: Indisponibilidade | D3: Lateral Movement | E3: A04:2021-Insecure Design | F3: Não | G3: Sim | H3: Sim | I3: Não
A4: O control plane deve seguir modelos de segurança adaptativo | B4: Cloud Security - Estruturante | C4: Vazamento de dados | D4: Elevation of Privilege | E4: A01:2021-Broken Access Control | F4: Não | G4: Sim | H4: Sim | I4: Não
A5: Especificar política a nível de organização para NÃO PERMITIR que portas de serviços sejam expostas para internet. Ex: 22, 1433, 1521, 3306, 3389, 5432, 6379, 6380, 8000, 8080, 27017 e 21 | B5: Cloud Security - Estruturante | C5: Vazamento de dados | D5: Tampering | E5: A05:2021-Security Misconfiguration | F5: Não | G5: Sim | H5: Sim | I5: Não
A6: Especificar política a nível de organização para NÃO PERMITIR exposição na internet de interfaces administrativas de recursos. | B6: Cloud Security - Estruturante | C6: Vazamento de dados | D6: Tampering | E6: A05:2021-Security Misconfiguration | F6: Não | G6: Sim | H6: Sim | I6: Não
A7: Especificar política a nível de organização para NÃO PERMITIR provisionamento de endereços sem filtragem de origem; destino e serviço/porta | B7: Cloud Security - Estruturante | C7: Vazamento de dados | D7: Tampering | E7: A02:2021-Cryptographic Failures | F7: Não | G7: Sim | H7: Sim | I7: Não
A8: Todos os recursos provisionados deveram estar com sua trilha de logs cyber habilitados | B8: Cloud Security - Estruturante | C8: Regulatório/Compliance | D8: Repudiation | E8: A09:2021-Security Logging and Monitoring Failures | F8: Não | G8: Sim | H8: Sim | I8: Não
A9: Recursos provisionados não podem ter interface exposta para a internet, o consumo deverá passar por camadas de proteção. | B9: Cloud Security - Estruturante | C9: Vazamento de dados | D9: Information Disclosure | E9: A02:2021-Cryptographic Failures | F9: Não | G9: Sim | H9: Sim | I9: Não
A10: Em novas construções de Landing Zone considerar a implementação dos Guardrails (políticas de segurança da Companhia) a nível do novo Tenant | B10: Cloud Security - Estruturante | C10: Vazamento de dados | D10: Tampering | F10: Não | G10: Sim | H10: Sim | I10: Não
A11: Integrar o tenant a ferramenta corporativa de CNAPP (mandatório as funções de CSPM e CWPP) | B11: Cloud Security - Estruturante | C11: Regulatório/Compliance | D11: Tampering | F11: Não | G11: Sim | H11: Sim | I11: Não
A12: Respeitar o processo de exceções estabelecido por governança | B12: Cloud Security - Estruturante | C12: Regulatório/Compliance | D12: Information Disclosure | F12: Não | G12: Sim | H12: Sim | I12: Não

Sheet Servidores
A1: Risco Iminente | B1: Risco Secundário | C1: Ameaça - Stride-LM | D1: Componente | E1: OWASP-10 | F1: Ameaça | G1: Controle | H1: Responsabilidade | I1: Aplicabilidade (On-Prem) | J1: Aplicabilidade (IAAS) | K1: Aplicabilidade (PAAS) | L1: Aplicabilidade (SAAS) | M1: Aplicabilidade (Mobile) | N1: Tecnologia/Processo recomendada | O1: Como fazer
A2: Vazamento de dados | B2: Danos a imagem | C2: Tampering, Repudiation | D2: Servidores | E2: A01:2021-Controle de acesso quebrado, A09:2021-Falhas de registro e monitoramento de segurança | F2: Roubo de credenciais | G2: Implementar autenticação multifatorial (MFA) para todas as contas | H2: Time de SO | I2: Sim | J2: Sim | K2: N/A | L2: N/A | M2: N/A | N2: Autheticator
A3: Vazamento de dados | B3: Regulatório/Compliance | C3: Tampering, Repudiation | D3: Servidores | E3: A01:2021-Controle de acesso quebrado, A09:2021-Falhas de registro e monitoramento de segurança | F3: Reutilização de credenciais | G3: O servidor deverá estar integrado a uma solução de PAM | H3: Time de SO | I3: Sim | J3: Sim | K3: N/A | L3: N/A | M3: N/A | N3: Autheticator
A4: Vazamento de dados | B4: Perda Financeira | C4: Tampering, Repudiation | D4: Servidores | E4: A01:2021-Controle de acesso quebrado, A09:2021-Falhas de registro e monitoramento de segurança | F4: Ataques de malware | G4: Todos os servidores devem possuir imagem de SO e BD padrão da Vivo (com EDR, Antivírus, agente do SIEM e agente de Scan de Infra) | H4: Time de SO | I4: Sim | J4: Sim | K4: N/A | L4: N/A | M4: N/A | N4: Autheticator
A5: Vazamento de dados | B5: Danos a imagem | C5: Information disclosure | D5: Servidores | E5: A04:2021 – Design Inseguro | F5: Movimentação lateral | H5: Time de SO | I5: Sim | J5: Sim | K5: N/A | L5: N/A | M5: N/A | N5: SIEM
A6: Vazamento de dados | B6: Regulatório/Compliance | C6: Information disclosure | D6: Servidores | E6: A04:2021 – Design Inseguro | F6: Acesso não autorizado | G6: Implementar políticas que garantam a retenção adequada de logs para auditoria e investigação. | H6: Time de SO | I6: Sim | J6: Sim | K6: N/A | L6: N/A | M6: N/A | N6: SIEM
A7: Vazamento de dados | C7: Information disclosure | D7: Servidores | E7: A04:2021 – Design Inseguro | F7: Man-In-the-Middle | G7: Implementar criptografia para dados em repouso e em trânsito, protegendo informações sensíveis de acesso não autorizado. | H7: Time de SO | I7: Sim | J7: Sim | K7: N/A | L7: N/A | M7: N/A | N7: Bitlocker (Windows), dm-crypt (Linux), TLS
A8: Vazamento de dados | B8: Regulatório/Compliance | C8: Information disclosure | D8: Servidores | E8: A04:2021 – Design Inseguro | F8: Vazamento de dados | H8: Time de SO | I8: Sim | J8: Sim | K8: N/A | L8: N/A | M8: N/A | N8: Bitlocker (Windows), dm-crypt (Linux), TLS
A9: Vazamento de dados | C9: Information disclosure | D9: Servidores | E9: A04:2021 – Design Inseguro | F9: Alteração dos dados | H9: Time de SO | I9: Sim | J9: Sim | K9: N/A | L9: N/A | M9: N/A | N9: Bitlocker (Windows), dm-crypt (Linux), TLS
A10: Vazamento de dados | B10: Regulatório/Compliance | C10: Information disclosure | D10: Servidores | E10: A04:2021 – Design Inseguro | F10: Exfiltração de dados | G10: Utilizar soluções de prevenção de perda de dados para monitorar e proteger dados sensíveis. | H10: Time de Proteção de dados | I10: Sim | J10: Sim | K10: N/A | L10: N/A | M10: N/A | N10: DLP, XDR
A11: Vazamento de dados | C11: Information disclosure | D11: Servidores | E11: A04:2021 – Design Inseguro | F11: Vazamento de dados | H11: Time de Proteção de dados | I11: Sim | J11: Sim | K11: N/A | L11: N/A | M11: N/A | N11: DLP, XDR
A12: Vazamento de dados | C12: Elevation of Privilege | D12: Servidores | E12: A01:2021-Controle de acesso quebrado | F12: Elevação de privilegio | G12: Implementar RBAC para gerenciar acesso a nivel infra | H12: Time de Gestão de acessos | I12: Sim | J12: Sim | K12: N/A | L12: N/A | M12: N/A | N12: IDP
A13: Vazamento de dados | C13: Lateral Movement | D13: Servidores | E13: A04:2021-Design inseguro | F13: Movimentação lateral | G13: Implementar segmentação de rede para limitar o movimento lateral | H13: Time de SO | I13: Sim | J13: Sim | K13: N/A | L13: N/A | M13: N/A | N13: Microsegmentação
G14: É necessário garantir que os projetos estejam com os SO adequados (não é permitido a subida de SO obsoleto) | H14: Time de SO | I14: Sim | J14: Sim | K14: N/A | L14: N/A | M14: N/A | N14: Hardenização
G15: O ativo precisa estar integrado ao CMDB, garantindo a centralização dos ativos no inventário oficial | H15: Time de TI | I15: Sim | J15: Sim | K15: N/A | L15: N/A | M15: N/A | N15: CMDB
G16: Todos os servidores devem possuir imagem de SO e BD padrão da Vivo (com EDR, Antivírus, agente do SIEM e agente de Scan de Infra) | H16: Time de SO | I16: Sim | J16: Sim | K16: N/A | L16: N/A | M16: N/A | N16: Hardenização

Sheet Versão3
A1: Risco Iminente | B1: Risco Secundário | C1: Ameaça - Stride-LM | D1: Componente | E1: OWASP-10 | F1: Ameaça | G1: Controle | H1: Responsabilidade | I1: Aplicabilidade (On-Prem) | J1: Aplicabilidade (IAAS) | K1: Aplicabilidade (PAAS) | L1: Aplicabilidade (SAAS) | M1: Aplicabilidade (Mobile) | N1: Tecnologia/Processo recomendada | O1: Como fazer
A2: Vazamento de dados | B2: Dano a imagem | C2: Information disclosure | D2: Aplicação | E2: A04:2021 – Design Inseguro | F2: Man-In-the-Middle | G2: Implementar a pinagem do Certificado Digital em soluções mobile | H2: Owner da aplicação | I2: N/A | J2: N/A | K2: N/A | L2: N/A | M2: Sim
A3: Vazamento de dados | B3: Dano a imagem | C3: Information disclosure | D3: Aplicação | E3: A02:2021 – Falhas Criptográficas | F3: Man-In-the-Middle | G3: Ativação da criptografia de payload e handshake entre front-end e camada de exposição de APIs | H3: Owner da aplicação | I3: Sim | J3: Sim | K3: Sim | L3: Sim | M3: Sim
A4: Vazamento de dados | B4: Perca financeira | C4: Spoofing | D4: Aplicação | E4: A09:2021 – Falhas de Segurança na Aplicação | F4: Roubo de sessão | G4: A aplicação deve implementar controle de sessão (timeout, sessão simultânea, etc) | H4: Owner da aplicação | I4: Sim | J4: Sim | K4: Sim | L4: Sim | M4: Sim
A5: Vazamento de dados | B5: Perca financeira | C5: Spoofing | D5: Aplicação | E5: A09:2021 – Falhas de Segurança na Aplicação | F5: Roubo de sessão | G5: A aplicação deve implementar validação de sessão (Front e Back via Mutual TLS) | H5: Owner da aplicação | I5: Sim | J5: Sim | K5: Sim | L5: Sim | M5: Sim
D6: Aplicação | G6: Implementar mecanismos para controle de Abuso de recursos/limite de requisições
D7: Aplicação | G7: Implementar mecanismos para bloqueio de ataques de “Brute Force” (exemplo: CAPTCH)
D8: Aplicação | G8: A aplicação deve efetuar a ofuscação de dados sensíveis, tanto no frontend quanto no backend
D9: Aplicação | G9: Prevenir mensagens de erro que permitam enumeração de usuários (Alterar as mensagens de retornos)
D10: Aplicação | G10: Garantir que cada token OTP (One Time Password), se aplicável, só possa ser usado uma única vez
D11: Aplicação | G11: Todas as aplicações WEB devem ser protegidas contra-ataques de CSRF (Cross Site Request Forgery) e CORS (Cross Origin Resource Sharing)
D12: Aplicação | G12: Os Bancos de Dados utilizados pela aplicação devem possuir uma rotina de backup documentada, aplicada e testada periodicamente
D13: Aplicação | G13: É necessário criptografar todas as comunicações entre o cliente e a API utilizando o protocolo TLS (HTTPs) 1.2 ou superior.
D14: Aplicação | G14: Utilize assinaturas digitais para garantir a autenticidade e a origem das mensagens, permitindo que a fonte seja verificada de forma irrefutável.
D15: Aplicação | G15: Caso o sistema/aplicação possa ser acessado à partir da Internet, ele precisa estar segregado por uma DMZ
D16: Aplicação | F16: Ataque de Força Bruta
C19: Tampering, Repudiation | D19: Servidores | E19: A01:2021-Controle de acesso quebrado, A09:2021-Falhas de registro e monitoramento de segurança | F19: Roubo de credenciais | G19: Implementar autenticação multifatorial (MFA) | H19: Time de SO | I19: Sim | J19: Sim | K19: N/A | L19: N/A | M19: N/A
C20: Tampering, Repudiation | D20: Servidores | E20: A01:2021-Controle de acesso quebrado, A09:2021-Falhas de registro e monitoramento de segurança | F20: Reutilização de credenciais | G20: Implementar autenticação multifatorial (MFA) | H20: Time de SO | I20: Sim | J20: Sim | K20: N/A | L20: N/A | M20: N/A
C21: Tampering, Repudiation | D21: Servidores | E21: A01:2021-Controle de acesso quebrado, A09:2021-Falhas de registro e monitoramento de segurança | F21: Ataques de malware | G21: Implementar autenticação multifatorial (MFA) | H21: Time de SO | I21: Sim | J21: Sim | K21: N/A | L21: N/A | M21: N/A
C22: Information Disclosure | D22: Servidores | E22: A04:2021 – Design Inseguro | F22: Movimentação lateral | G22: Implementar políticas que garantam a retenção adequada de logs para auditoria e investigação. | H22: Time de SO | I22: Sim | J22: Sim | K22: N/A | L22: N/A | M22: N/A
C23: Information Disclosure | D23: Servidores | E23: A04:2021 – Design Inseguro | F23: Acesso não autorizado | G23: Implementar políticas que garantam a retenção adequada de logs para auditoria e investigação. | H23: Time de SO | I23: Sim | J23: Sim | K23: N/A | L23: N/A | M23: N/A
C24: Information disclosure | D24: Servidores | E24: A04:2021 – Design Inseguro | F24: Man-In-the-Middle | G24: Implementar criptografia para dados em repouso e em trânsito, protegendo informações sensíveis de acesso não autorizado. | H24: Time de SO | I24: Sim | J24: Sim | K24: N/A | L24: N/A | M24: N/A
C25: Information disclosure | D25: Servidores | E25: A04:2021 – Design Inseguro | F25: Vazamento de dados | G25: Implementar criptografia para dados em repouso e em trânsito, protegendo informações sensíveis de acesso não autorizado. | H25: Time de SO | I25: Sim | J25: Sim | K25: N/A | L25: N/A | M25: N/A
C26: Information disclosure | D26: Servidores | E26: A04:2021 – Design Inseguro | F26: Alteração dos dados | G26: Implementar criptografia para dados em repouso e em trânsito, protegendo informações sensíveis de acesso não autorizado. | H26: Time de SO | I26: Sim | J26: Sim | K26: N/A | L26: N/A | M26: N/A
C27: Information disclosure | D27: Servidores | E27: A04:2021 – Design Inseguro | F27: Exfiltração de dados | G27: Utilizar soluções de prevenção de perda de dados para monitorar e proteger dados sensíveis. | H27: Time de Proteção de dados | I27: Sim | J27: Sim | K27: N/A | L27: N/A | M27: N/A
C28: Information disclosure | D28: Servidores | E28: A04:2021 – Design Inseguro | F28: Vazamento de dados | G28: Utilizar soluções de prevenção de perda de dados para monitorar e proteger dados sensíveis. | H28: Time de Proteção de dados | I28: Sim | J28: Sim | K28: N/A | L28: N/A | M28: N/A
C29: Elevation of Privilege | D29: Servidores | E29: A01:2021-Controle de acesso quebrado | F29: Elevação de privilegio | G29: Implementar RBAC para gerenciar acesso | H29: Time de Gestão de acessos | I29: Sim | J29: Sim | K29: N/A | L29: N/A | M29: N/A
C30: Lateral Movement | D30: Servidores | E30: A04:2021-Design inseguro | F30: Movimentação lateral | G30: Implementar segmentação de rede para limitar o movimento lateral | H30: Time de SO | I30: Sim | J30: Sim | K30: N/A | L30: N/A | M30: N/A
D45: Banco de Dados | F45: Injeção SQL | G45: O Banco de Dados deve utilizar validações de entrada para evitar ataques de injeção, como SQL injection, que podem comprometer a integridade dos dados.
D46: Banco de Dados | F46: Ataque de Força Bruta
D47: Banco de Dados | F47: Ataque Man-in-the-Middle (MITM)
D48: Banco de Dados | F48: Exploração de Zero-Day
D49: Banco de Dados | F49: Uso de Credenciais Roubadas
D50: Banco de Dados | F50: Privilégios Excessivos
D51: Banco de Dados | F51: Erros de Configuração
D52: Banco de Dados | F52: Dados Expostos Publicamente
D53: Banco de Dados | F53: Negação de Serviço (DoS/DDoS)
D54: Banco de Dados | F54: Locking e Deadlocks
D55: Banco de Dados | F55: Falta de Criptografia
D56: Banco de Dados | F56: Falta de Backup e Recuperação
...

Sheet Versão2
A1: Risco Iminente | B1: Risco Secundário | C1: Ameaça - Stride-LM | D1: Componente | E1: OWASP-10 | F1: Controle de Ameaças | G1: Responsabilidade | H1: Aplicabilidade (On-Prem) | I1: Aplicabilidade (IAAS) | J1: Aplicabilidade (PAAS) | K1: Aplicabilidade (SAAS) | L1: Tecnologia/Processo recomendada | M1: Como fazer
A2: Vazamento de Dados | B2: Regulatório/Compliance | C2: Spoofing | D2: Workstation | E2: A9 - Quebra de criptografia | F2: Criptografia de Disco | G2: TI/Workplace | H2: sim | I2: sim | J2: sim | K2: sim | L2: Bitlocker | M2: Falta normativa/modelo para esse controle
A3: Vazamento de Dados | C3: Ransomware | D3: Workstation | F3: Sistemas Operacionais e Softwares Atualizados (Patches atualizados) | G3: Owner/Proteção de Dados | H3: sim | I3: sim | J3: não | K3: não
A4: Vazamento de Dados | C4: Ransomware | D4: Workstation | F4: Politicas de privilegio minimo | G4: Owner/Proteção de Dados | H4: sim | I4: sim | J4: não | K4: não
A5: Vazamento de Dados | C5: Ransomware | D5: Workstation | F5: Detecção e Respostas a Ponto de Extremidades (EDR) | G5: Owner/Proteção de Dados | H5: sim | I5: sim | J5: não | K5: não
A6: Vazamento de Dados | C6: Ransomware | D6: Workstation | F6: Proteção de perda de dados (DLP) | G6: Owner/Proteção de Dados | H6: sim | I6: sim | J6: não | K6: não
A7: Vazamento de Dados | C7: Ransomware | D7: Workstation | F7: Backup imutavel | G7: Owner/Proteção de Dados | H7: sim | I7: sim | J7: não | K7: não
A8: Vazamento de Dados | C8: Ransomware | D8: Workstation | F8: Detecção e Respostas a Ponto de Extremidades (EDR) | G8: Owner/Proteção de Dados | H8: sim | I8: sim | J8: não | K8: não
A9: Vazamento de Dados | C9: Ransomware | D9: Workstation | F9: Proteção de perda de dados (DLP) | G9: Owner/Proteção de Dados | H9: sim | I9: sim | J9: não | K9: não
A10: Vazamento de Dados | C10: Ransomware | D10: Workstation | F10: Backup imutavel | G10: Owner/Proteção de Dados
A11: Vazamento de Dados | C11: Ransomware | D11: Workstation | F11: Segmentação de redes | G11: Owner/Proteção de Dados
A12: Vazamento de Dados | C12: Ransomware | D12: Workstation | F12: Segmentação de redes | G12: Owner/Proteção de Dados
A13: Vazamento de Dados | C13: Ransomware | D13: Workstation | F13: Backup imutavel | G13: Owner/Proteção de Dados
A14: Vazamento de Dados | C14: Ransomware | D14: Workstation | F14: Restringir acesso administrativo | G14: Owner/Proteção de Dados
A15: Vazamento de Dados | C15: Ransomware | D15: Workstation | F15: Segmentação de redes | G15: Owner/Proteção de Dados
A16: Vazamento de Dados | C16: Ransomware | D16: Workstation | F16: Backup imutavel | G16: Owner/Proteção de Dados
A17: Vazamento de Dados | C17: Ransomware | D17: Workstation | F17: Autenticação forte | G17: Owner/Proteção de Dados
A18: Vazamento de Dados | C18: Ransomware | D18: Workstation | F18: Politicas de privilegio minimo | G18: Owner/Proteção de Dados
A19: Vazamento de Dados | C19: Credenciais comprometidas | D19: Workstation | F19: Segmentação de perfis de acesso
A20: Vazamento de Dados | C20: Credenciais comprometidas | D20: Servidores Fisicos | F20: Política e procedimentos de controle de acesso, revisão de acesso
A21: Vazamento de Dados | C21: Exposição de dados em nuvem | D21: Maquinas Virtuais
A22: Vazamento de Dados | C22: Acessos não autorizados | D22: Containers
A23: Vazamento de Dados | C23: Elevação de Privilegio | D23: Serviços Serveless
A24: Vazamento de Dados | C24: Misconfiguration | D24: Bancos Relacionais
A25: Vazamento de Dados | C25: Espionagem Industrial | D25: Storage em bloco ou objeto
A26: Vazamento de Dados | C26: Insider Threats | D26: Balanceadores de carga
A27: Vazamento de Dados | C27: Man-in-the-Middle | D27: Firewalls
A28: Vazamento de Dados | C28: Exploração de Vulnerabilidades em aplicações Web | D28: DNS
A29: Vazamento de Dados | C29: Adulteração de dados | D29: Redes privadas virtuais
A30: Vazamento de Dados | C30: Exposição acidental | D30: Gateways de API
A31: Vazamento de Dados | C31: Ataques a Sistemas Legados | D31: Filas de Mensagem
D32: Streams de dados
C33: Tampering | D33: Banco de Dados | E33: A03:2021 – Injeção | F33: Injeção SQL
C34: Spoofing, Elevation of Privilege | D34: Banco de Dados | E34: A07:2021 – Falhas de Identificação e Autenticação | F34: Ataque de Força Bruta
D35: Banco de Dados | E35: A02:2021 – Falhas Criptográficas | F35: Ataque Man-in-the-Middle (MITM)
D36: Banco de Dados | E36: A06:2021 – Componentes Vulneráveis e Desatualizados | F36: Exploração de Zero-Day
C37: Spoofing, Elevation of Privilege | D37: Banco de Dados | E37: A07:2021 – Falhas de Identificação e Autenticação | F37: Uso de Credenciais Roubadas
C38: Tampering, Information disclosure | D38: Banco de Dados | E38: A05:2021 – Configuração Insegura | F38: Privilégios Excessivos
C39: Tampering, Information disclosure | D39: Banco de Dados | E39: A05:2021 – Configuração Insegura | F39: Erros de Configuração
C40: Elevation of Privilege | D40: Banco de Dados | E40: A01:2021 – Controle de Acesso Quebrado | F40: Dados Expostos Publicamente
...

Sheet Versão1
A1: Risco | B1: Ameaça - Stride-LM | C1: Componente | D1: OWASP-10 | E1: Controle de Ameaças | G1: Responsabilidade | H1: Aplicabilidade (On-Prem) | I1: Aplicabilidade (IAAS) | J1: Aplicabilidade (PAAS) | K1: Aplicabilidade (SAAS) | L1: Tecnologia/Processo recomendada | M1: Como fazer
B2: Phishing | C2: Aplicação | E2: Autenticação Multiplo Fator de Autenticação | G2: Owner/Proteção de Dados | H2: sim | I2: sim | J2: sim | K2: sim | L2: OAM/Authenticator de mercado | M2: LINK DA NORMATIVA/SHAREPOINT
A3: Vazamento de Dados | B3: Ransomware | C3: Sistema Operacional | E3: Sistemas Operacionais e Softwares Atualizados (Patches atualizados) | G3: Owner/Proteção de Dados | H3: sim | I3: sim | J3: não | K3: não
A4: Vazamento de Dados | B4: Ransomware | C4: Sistema Operacional | E4: Politicas de privilegio minimo | G4: Owner/Proteção de Dados | H4: sim | I4: sim | J4: não | K4: não
A5: Vazamento de Dados | B5: Ransomware | C5: Sistema Operacional | E5: Detecção e Respostas a Ponto de Extremidades (EDR) | G5: Owner/Proteção de Dados | H5: sim | I5: sim | J5: não | K5: não
A6: Vazamento de Dados | B6: Ransomware | C6: Servidores de arquivos | E6: Proteção de perda de dados (DLP) | G6: Owner/Proteção de Dados | H6: sim | I6: sim | J6: não | K6: não
A7: Vazamento de Dados | B7: Ransomware | C7: Servidores de arquivos | E7: Backup imutavel | G7: Owner/Proteção de Dados | H7: sim | I7: sim | J7: não | K7: não
A8: Vazamento de Dados | B8: Ransomware | C8: Endpoint de acesso usuário | E8: Detecção e Respostas a Ponto de Extremidades (EDR) | G8: Owner/Proteção de Dados | H8: sim | I8: sim | J8: não | K8: não
A9: Vazamento de Dados | B9: Ransomware | C9: Endpoint de acesso usuário | E9: Proteção de perda de dados (DLP) | G9: Owner/Proteção de Dados | H9: sim | I9: sim | J9: não | K9: não
A10: Vazamento de Dados | B10: Ransomware | C10: Banco de dados | E10: Backup imutavel | G10: Owner/Proteção de Dados
A11: Vazamento de Dados | B11: Ransomware | C11: Banco de dados | E11: Segmentação de redes | G11: Owner/Proteção de Dados
A12: Vazamento de Dados | B12: Ransomware | C12: Backups | E12: Segmentação de redes | G12: Owner/Proteção de Dados
A13: Vazamento de Dados | B13: Ransomware | C13: Backups | E13: Backup imutavel | G13: Owner/Proteção de Dados
A14: Vazamento de Dados | B14: Ransomware | C14: Servidores de serviço | E14: Restringir acesso administrativo | G14: Owner/Proteção de Dados
A15: Vazamento de Dados | B15: Ransomware | C15: Servidores de serviço | E15: Segmentação de redes | G15: Owner/Proteção de Dados
A16: Vazamento de Dados | B16: Ransomware | C16: Servidores de serviço | E16: Backup imutavel | G16: Owner/Proteção de Dados
A17: Vazamento de Dados | B17: Ransomware | C17: API | E17: autenticação forte | G17: Owner/Proteção de Dados
A18: Vazamento de Dados | B18: Ransomware | C18: API | E18: Politicas de privilegio minimo | G18: Owner/Proteção de Dados
A19: Vazamento de Dados | B19: Credenciais comprometidas | C19: Aplicação | E19: Segmentação de perfis de acesso
A20: Vazamento de Dados | B20: Credenciais comprometidas | E20: Política e procedimentos de controle de acesso, revisão de acesso
A21: Vazamento de Dados | B21: Exposição de dados em nuvem
A22: Vazamento de Dados | B22: Acessos não autorizados
A23: Vazamento de Dados | B23: Elevação de Privilegio
A24: Vazamento de Dados | B24: Misconfiguration
A25: Vazamento de Dados | B25: Espionagem Industrial
A26: Vazamento de Dados | B26: Insider Threats
A27: Vazamento de Dados | B27: Man-in-the-Middle
A28: Vazamento de Dados | B28: Exploração de Vulnerabilidades em aplicações Web
A29: Vazamento de Dados | B29: Adulteração de dados
A30: Vazamento de Dados | B30: Exposição acidental
A31: Vazamento de Dados | B31: Ataques a Sistemas Legados
A32: Regulatório/Compliance | B32: Exposição de dados sensiveis
... A52: Danos a imagem | B52: Configurações erradas e acessos expostos

Sheet NewVersion
A1: Controle/Correlação | B1: Detalhamento do requisito | C1: Componente | D1: Propriedade | E1: STRIDE LM | F1: Riscos/Impacto | G1: OWASP-TOP10 | H1: Estrutura - Sistema de Informação | I1: Categoria de Segurança | J1: On-Prem | K1: IaaS | L1: PaaS | M1: SaaS | N1: Tecnologia/Processo | O1: Como fazer
A2: A aplicação deve ativar a criptografia de payload e handshake entre front-end e camada de exposição de APIs | B2: A criptografia assegura que dados sensíveis trocados entre o cliente e o servidor sejam protegidos contra interceptação. O risco de não aplicar isso é a exposição e/ou modificação de dados pessoais e confidenciais a ataques como Man-in-the-Middle (MITM). | C2: Aplicação - Web/Mobile | D2: {=IF(Tabela1[[#This Row],[STRIDE LM]]="Information Disclosure",Formatação!H$5,IF(Tabela1[[#This Row],[STRIDE LM]]="Repudiation",Formatação!H$4,IF(Tabela1[[#This Row],[STRIDE LM]]="Spoofing",Formatação!H$2,IF(Tabela1[[#This Row],[STRIDE LM]]="Tampering",Formatação!H$3, IF(Tabela1[[#This Row],[STRIDE LM]]="Denial of Service",Formatação!H$6,IF(Tabela1[[#This Row],[STRIDE LM]]="Elevation of Privilege",Formatação!H$7,IF(Tabela1[[#This Row],[STRIDE LM]]="Lateral Movement",Formatação!H$8,Errado)))))))} -> Integridade | E2: Tampering | F2: {=IF(Tabela1[[#This Row],[STRIDE LM]]="Information Disclosure",Formatação!J$5,IF(Tabela1[[#This Row],[STRIDE LM]]="Repudiation",Formatação!J$4,IF(Tabela1[[#This Row],[STRIDE LM]]="Spoofing",Formatação!J$2,IF(Tabela1[[#This Row],[STRIDE LM]]="Tampering",Formatação!J$3, IF(Tabela1[[#This Row],[STRIDE LM]]="Denial of Service",Formatação!J$6,IF(Tabela1[[#This Row],[STRIDE LM]]="Elevation of Privilege",Formatação!J$7,IF(Tabela1[[#This Row],[STRIDE LM]]="Lateral Movement",Formatação!J$8,Errado)))))))} -> Danos a imagem | G2: A02:2021-Cryptographic Failures | H2: Processamento | I2: Application Security | J2: Sim | K2: Sim | L2: Sim | M2: Não | N2: Criptografia de payload / Deve ser implmentado durante o desenvolvimento | O2: Em construção
A3: Prevenir mensagens de erro que permitam enumeração de usuários (Alterar as mensagens de retornos) | B3: Mensagens de erro genéricas evitam que invasores possam identificar a existência de um usuário específico. Caso contrário, o risco de ataques de força bruta ou enumeração de usuários aumenta. | C3: Aplicação - Web/Mobile | D3: {=IF(Tabela1[[#This Row],[STRIDE LM]]="Information Disclosure",Formatação!H$5,IF(Tabela1[[#This Row],[STRIDE LM]]="Repudiation",Formatação!H$4,IF(Tabela1[[#This Row],[STRIDE LM]]="Spoofing",Formatação!H$2,IF(Tabela1[[#This Row],[STRIDE LM]]="Tampering",Formatação!H$3, IF(Tabela1[[#This Row],[STRIDE LM]]="Denial of Service",Formatação!H$6,IF(Tabela1[[#This Row],[STRIDE LM]]="Elevation of Privilege",Formatação!H$7,IF(Tabela1[[#This Row],[STRIDE LM]]="Lateral Movement",Formatação!H$8,Errado)))))))} -> Confidencialidade | E3: Information Disclosure | F3: {=IF(Tabela1[[#This Row],[STRIDE LM]]="Information Disclosure",Formatação!J$5,IF(Tabela1[[#This Row],[STRIDE LM]]="Repudiation",Formatação!J$4,IF(Tabela1[[#This Row],[STRIDE LM]]="Spoofing",Formatação!J$2,IF(Tabela1[[#This Row],[STRIDE LM]]="Tampering",Formatação!J$3, IF(Tabela1[[#This Row],[STRIDE LM]]="Denial of Service",Formatação!J$6,IF(Tabela1[[#This Row],[STRIDE LM]]="Elevation of Privilege",Formatação!J$7,IF(Tabela1[[#This Row],[STRIDE LM]]="Lateral Movement",Formatação!J$8,Errado)))))))} -> Vazamento de dados | G3: A04:2021-Insecure Design | J3: Sim | K3: Sim | L3: Sim | M3: Não | N3: Code Review (DAST)
A4: A aplicação precisa estar protegida com um Web Application Firewall (WAF) - Definições de politicas Telefonica | B4: O WAF monitora o tráfego HTTP e impede ataques como SQL Injection, XSS e outros direcionados à camada de aplicação. Não implementar pode deixar a aplicação vulnerável a ataques conhecidos e comprometimentos de segurança. | C4: Aplicação - Web/Mobile | D4: {=IF(Tabela1[[#This Row],[STRIDE LM]]="Information Disclosure",Formatação!H$5,IF(Tabela1[[#This Row],[STRIDE LM]]="Repudiation",Formatação!H$4,IF(Tabela1[[#This Row],[STRIDE LM]]="Spoofing",Formatação!H$2,IF(Tabela1[[#This Row],[STRIDE LM]]="Tampering",Formatação!H$3, IF(Tabela1[[#This Row],[STRIDE LM]]="Denial of Service",Formatação!H$6,IF(Tabela1[[#This Row],[STRIDE LM]]="Elevation of Privilege",Formatação!H$7,IF(Tabela1[[#This Row],[STRIDE LM]]="Lateral Movement",Formatação!H$8,Errado)))))))} -> Disponibilidade | E4: Denial of Service | F4: {=IF(Tabela1[[#This Row],[STRIDE LM]]="Information Disclosure",Formatação!J$5,IF(Tabela1[[#This Row],[STRIDE LM]]="Repudiation",Formatação!J$4,IF(Tabela1[[#This Row],[STRIDE LM]]="Spoofing",Formatação!J$2,IF(Tabela1[[#This Row],[STRIDE LM]]="Tampering",Formatação!J$3, IF(Tabela1[[#This Row],[STRIDE LM]]="Denial of Service",Formatação!J$6,IF(Tabela1[[#This Row],[STRIDE LM]]="Elevation of Privilege",Formatação!J$7,IF(Tabela1[[#This Row],[STRIDE LM]]="Lateral Movement",Formatação!J$8,Errado)))))))} -> Indisponibilidade | G4: A05:2021-Security Misconfiguration | J4: Não | K4: Sim | L4: Sim | M4: Sim | N4: Implementar rate limiting, requisições com challenge (CAPTCHA), balanceamento de carga e detecção de tráfego anômalo via SIEM. | O4: Configurar rate limiting no API Gateway; Integrar SIEM para alertar sobre picos anormais.
A5: Para implantações em pipelines de CI/CD, é essencial que vulnerabilidades classificadas como altas e críticas sejam corrigidas antes de serem levadas para o ambiente de produção. | B5: Corrigir vulnerabilidades críticas antes da produção reduz a chance de exploração por atacantes. Ignorar vulnerabilidades críticas pode resultar em falhas de segurança graves após o lançamento. | C5: Aplicação - Web/Mobile | D5: {=IF(Tabela1[[#This Row],[STRIDE LM]]="Information Disclosure",Formatação!H$5,IF(Tabela1[[#This Row],[STRIDE LM]]="Repudiation",Formatação!H$4,IF(Tabela1[[#This Row],[STRIDE LM]]="Spoofing",Formatação!H$2,IF(Tabela1[[#This Row],[STRIDE LM]]="Tampering",Formatação!H$3, IF(Tabela1[[#This Row],[STRIDE LM]]="Denial of Service",Formatação!H$6,IF(Tabela1[[#This Row],[STRIDE LM]]="Elevation of Privilege",Formatação!H$7,IF(Tabela1[[#This Row],[STRIDE LM]]="Lateral Movement",Formatação!H$8,Errado)))))))} -> Confidencialidade | E5: Information Disclosure | F5: {=IF(Tabela1[[#This Row],[STRIDE LM]]="Information Disclosure",Formatação!J$5,IF(Tabela1[[#This Row],[STRIDE LM]]="Repudiation",Formatação!J$4,IF(Tabela1[[#This Row],[STRIDE LM]]="Spoofing",Formatação!J$2,IF(Tabela1[[#This Row],[STRIDE LM]]="Tampering",Formatação!J$3, IF(Tabela1[[#This Row],[STRIDE LM]]="Denial of Service",Formatação!J$6,IF(Tabela1[[#This Row],[STRIDE LM]]="Elevation of Privilege",Formatação!J$7,IF(Tabela1[[#This Row],[STRIDE LM]]="Lateral Movement",Formatação!J$8,Errado)))))))} -> Vazamento de dados | G5: A06:2021-Vulnerable and Outdated Components | J5: Sim | K5: Sim | L5: Sim | M5: Sim | N5: Utilização de vaults de segredo (AWS Secrets Manager, HashiCorp Vault), revisão de código com ferramentas DAST e proibição de segredos em repositórios Git. | O5: Configurar CI/CD para bloquear commits com segredos expostos.
A6: Caso o sistema/aplicação possa ser acessado à partir da Internet, ele precisa estar segregado por uma DMZ | B6: A DMZ oferece uma camada extra de segurança, isolando sistemas críticos de acessos diretos da internet. A ausência de uma DMZ pode resultar em acesso não autorizado a sistemas internos. | C6: Aplicação - Web/Mobile | D6: {=IF(Tabela1[[#This Row],[STRIDE LM]]="Information Disclosure",Formatação!H$5,IF(Tabela1[[#This Row],[STRIDE LM]]="Repudiation",Formatação!H$4,IF(Tabela1[[#This Row],[STRIDE LM]]="Spoofing",Formatação!H$2,IF(Tabela1[[#This Row],[STRIDE LM]]="Tampering",Formatação!H$3, IF(Tabela1[[#This Row],[STRIDE LM]]="Denial of Service",Formatação!H$6,IF(Tabela1[[#This Row],[STRIDE LM]]="Elevation of Privilege",Formatação!H$7,IF(Tabela1[[#This Row],[STRIDE LM]]="Lateral Movement",Formatação!H$8,Errado)))))))} -> Disponibilidade | E6: Denial of Service | F6: {=IF(Tabela1[[#This Row],[STRIDE LM]]="Information Disclosure",Formatação!J$5,IF(Tabela1[[#This Row],[STRIDE LM]]="Repudiation",Formatação!J$4,IF(Tabela1[[#This Row],[STRIDE LM]]="Spoofing",Formatação!J$2,IF(Tabela1[[#This Row],[STRIDE LM]]="Tampering",Formatação!J$3, IF(Tabela1[[#This Row],[STRIDE LM]]="Denial of Service",Formatação!J$6,IF(Tabela1[[#This Row],[STRIDE LM]]="Elevation of Privilege",Formatação!J$7,IF(Tabela1[[#This Row],[STRIDE LM]]="Lateral Movement",Formatação!J$8,Errado)))))))} -> Indisponibilidade | G6: A04:2021-Insecure Design | J6: Sim | K6: Sim | L6: Sim | M6: Não | N6: Arquitetura Segura | O6: Em tempo de analise do projeto
A7: A aplicação deve implementar a pinagem do certificado digital em soluções mobile (Evitar MITM) | B7: A pinagem de certificado impede ataques MITM, garantindo que o certificado do servidor seja sempre validado. Caso contrário, um atacante poderia interceptar a comunicação. | C7: Aplicação - Web/Mobile | D7: {=IF(Tabela1[[#This Row],[STRIDE LM]]="Information Disclosure",Formatação!H$5,IF(Tabela1[[#This Row],[STRIDE LM]]="Repudiation",Formatação!H$4,IF(Tabela1[[#This Row],[STRIDE LM]]="Spoofing",Formatação!H$2,IF(Tabela1[[#This Row],[STRIDE LM]]="Tampering",Formatação!H$3, IF(Tabela1[[#This Row],[STRIDE LM]]="Denial of Service",Formatação!H$6,IF(Tabela1[[#This Row],[STRIDE LM]]="Elevation of Privilege",Formatação!H$7,IF(Tabela1[[#This Row],[STRIDE LM]]="Lateral Movement",Formatação!H$8,Errado)))))))} -> Autenticação | E7: Spoofing | F7: {=IF(Tabela1[[#This Row],[STRIDE LM]]="Information Disclosure",Formatação!J$5,IF(Tabela1[[#This Row],[STRIDE LM]]="Repudiation",Formatação!J$4,IF(Tabela1[[#This Row],[STRIDE LM]]="Spoofing",Formatação!J$2,IF(Tabela1[[#This Row],[STRIDE LM]]="Tampering",Formatação!J$3, IF(Tabela1[[#This Row],[STRIDE LM]]="Denial of Service",Formatação!J$6,IF(Tabela1[[#This Row],[STRIDE LM]]="Elevation of Privilege",Formatação!J$7,IF(Tabela1[[#This Row],[STRIDE LM]]="Lateral Movement",Formatação!J$8,Errado)))))))} -> Fraudes/Vazamento de dados | G7: A02:2021-Cryptographic Failures | J7: Sim | K7: Sim | L7: Sim | M7: Não | N7: Desenvolvimento Seguro
A8: A aplicação deve implementar Controle de Sessão (timeout, sessão simultânea, etc) | B8: Controlar sessões previne que sessões inativas ou múltiplas simultâneas comprometam a segurança do sistema. A falta de controle pode levar a invasões de contas por sessões esquecidas ou mal gerenciadas. | C8: Aplicação - Web/Mobile | D8: {=IF(Tabela1[[#This Row],[STRIDE LM]]="Information Disclosure",Formatação!H$5,IF(Tabela1[[#This Row],[STRIDE LM]]="Repudiation",Formatação!H$4,IF(Tabela1[[#This Row],[STRIDE LM]]="Spoofing",Formatação!H$2,IF(Tabela1[[#This Row],[STRIDE LM]]="Tampering",Formatação!H$3, IF(Tabela1[[#This Row],[STRIDE LM]]="Denial of Service",Formatação!H$6,IF(Tabela1[[#This Row],[STRIDE LM]]="Elevation of Privilege",Formatação!H$7,IF(Tabela1[[#This Row],[STRIDE LM]]="Lateral Movement",Formatação!H$8,Errado)))))))} -> Autenticação | E8: Spoofing | F8: {=IF(Tabela1[[#This Row],[STRIDE LM]]="Information Disclosure",Formatação!J$5,IF(Tabela1[[#This Row],[STRIDE LM]]="Repudiation",Formatação!J$4,IF(Tabela1[[#This Row],[STRIDE LM]]="Spoofing",Formatação!J$2,IF(Tabela1[[#This Row],[STRIDE LM]]="Tampering",Formatação!J$3, IF(Tabela1[[#This Row],[STRIDE LM]]="Denial of Service",Formatação!J$6,IF(Tabela1[[#This Row],[STRIDE LM]]="Elevation of Privilege",Formatação!J$7,IF(Tabela1[[#This Row],[STRIDE LM]]="Lateral Movement",Formatação!J$8,Errado)))))))} -> Fraudes/Vazamento de dados | G8: A01:2021-Broken Access Control | J8: Sim | K8: Sim | L8: Sim | M8: Sim | N8: Desenvolvimento Seguro
A9: A aplicação de implementar validação de Sessão (Front e Back via Mutual TLS) | B9: A validação de sessão com Mutual TLS garante que tanto o cliente quanto o servidor sejam autenticados mutuamente, prevenindo acesso não autorizado. Sem isso, a aplicação fica vulnerável a sequestro de sessão. | C9: Aplicação - Web/Mobile | D9: {=IF(Tabela1[[#This Row],[STRIDE LM]]="Information Disclosure",Formatação!H$5,IF(Tabela1[[#This Row],[STRIDE LM]]="Repudiation",Formatação!H$4,IF(Tabela1[[#This Row],[STRIDE LM]]="Spoofing",Formatação!H$2,IF(Tabela1[[#This Row],[STRIDE LM]]="Tampering",Formatação!H$3, IF(Tabela1[[#This Row],[STRIDE LM]]="Denial of Service",Formatação!H$6,IF(Tabela1[[#This Row],[STRIDE LM]]="Elevation of Privilege",Formatação!H$7,IF(Tabela1[[#This Row],[STRIDE LM]]="Lateral Movement",Formatação!H$8,Errado)))))))} -> Autenticação | E9: Spoofing | F9: {=IF(Tabela1[[#This Row],[STRIDE LM]]="Information Disclosure",Formatação!J$5,IF(Tabela1[[#This Row],[STRIDE LM]]="Repudiation",Formatação!J$4,IF(Tabela1[[#This Row],[STRIDE LM]]="Spoofing",Formatação!J$2,IF(Tabela1[[#This Row],[STRIDE LM]]="Tampering",Formatação!J$3, IF(Tabela1[[#This Row],[STRIDE LM]]="Denial of Service",Formatação!J$6,IF(Tabela1[[#This Row],[STRIDE LM]]="Elevation of Privilege",Formatação!J$7,IF(Tabela1[[#This Row],[STRIDE LM]]="Lateral Movement",Formatação!J$8,Errado)))))))} -> Fraudes/Vazamento de dados | G9: A01:2021-Broken Access Control | J9: Sim | K9: Sim | L9: Sim | M9: Sim | N9: Desenvolvimento Seguro
A10: A aplicação deve efetuar a ofuscação de dados sensíveis, tanto no frontend quanto no backend | B10: Ofuscar dados sensíveis ajuda a evitar que informações como senhas ou detalhes pessoais sejam facilmente acessadas em caso de comprometimento. A falta de ofuscação pode resultar em vazamentos de dados sensíveis. | C10: Aplicação - Web/Mobile | D10: {=IF(Tabela1[[#This Row],[STRIDE LM]]="Information Disclosure",Formatação!H$5,IF(Tabela1[[#This Row],[STRIDE LM]]="Repudiation",Formatação!H$4,IF(Tabela1[[#This Row],[STRIDE LM]]="Spoofing",Formatação!H$2,IF(Tabela1[[#This Row],[STRIDE LM]]="Tampering",Formatação!H$3, IF(Tabela1[[#This Row],[STRIDE LM]]="Denial of Service",Formatação!H$6,IF(Tabela1[[#This Row],[STRIDE LM]]="Elevation of Privilege",Formatação!H$7,IF(Tabela1[[#This Row],[STRIDE LM]]="Lateral Movement",Formatação!H$8,Errado)))))))} -> Confidencialidade | E10: Information Disclosure | F10: {=IF(Tabela1[[#This Row],[STRIDE LM]]="Information Disclosure",Formatação!J$5,IF(Tabela1[[#This Row],[STRIDE LM]]="Repudiation",Formatação!J$4,IF(Tabela1[[#This Row],[STRIDE LM]]="Spoofing",Formatação!J$2,IF(Tabela1[[#This Row],[STRIDE LM]]="Tampering",Formatação!J$3, IF(Tabela1[[#This Row],[STRIDE LM]]="Denial of Service",Formatação!J$6,IF(Tabela1[[#This Row],[STRIDE LM]]="Elevation of Privilege",Formatação!J$7,IF(Tabela1[[#This Row],[STRIDE LM]]="Lateral Movement",Formatação!J$8,Errado)))))))} -> Vazamento de dados | G10: A02:2021-Cryptographic Failures | J10: Sim | K10: Sim | L10: Sim | M10: Sim | N10: Desenvolvimento Seguro
A11: Todas as aplicações WEB devem ser protegidas contra-ataques de CSRF (Cross Site Request Forgery) e CORS (Cross Origin Resource Sharing) | B11: Prevenir CSRF e configurar CORS adequadamente evita que ataques externos possam executar ações não autorizadas em nome de um usuário legítimo. Ignorar isso pode permitir ataques de escalonamento de privilégio. | C11: Aplicação - Web/Mobile | D11: {=IF(Tabela1[[#This Row],[STRIDE LM]]="Information Disclosure",Formatação!H$5,IF(Tabela1[[#This Row],[STRIDE LM]]="Repudiation",Formatação!H$4,IF(Tabela1[[#This Row],[STRIDE LM]]="Spoofing",Formatação!H$2,IF(Tabela1[[#This Row],[STRIDE LM]]="Tampering",Formatação!H$3, IF(Tabela1[[#This Row],[STRIDE LM]]="Denial of Service",Formatação!H$6,IF(Tabela1[[#This Row],[STRIDE LM]]="Elevation of Privilege",Formatação!H$7,IF(Tabela1[[#This Row],[STRIDE LM]]="Lateral Movement",Formatação!H$8,Errado)))))))} -> Integridade | E11: Tampering | F11: {=IF(Tabela1[[#This Row],[STRIDE LM]]="Information Disclosure",Formatação!J$5,IF(Tabela1[[#This Row],[STRIDE LM]]="Repudiation",Formatação!J$4,IF(Tabela1[[#This Row],[STRIDE LM]]="Spoofing",Formatação!J$2,IF(Tabela1[[#This Row],[STRIDE LM]]="Tampering",Formatação!J$3, IF(Tabela1[[#This Row],[STRIDE LM]]="Denial of Service",Formatação!J$6,IF(Tabela1[[#This Row],[STRIDE LM]]="Elevation of Privilege",Formatação!J$7,IF(Tabela1[[#This Row],[STRIDE LM]]="Lateral Movement",Formatação!J$8,Errado)))))))} -> Danos a imagem | G11: A03:2021-Injection | J11: Sim | K11: Sim | L11: Sim | M11: Sim | N11: Desenvolvimento Seguro
A12: A aplicação deve implementar validação de Sessão (Front e Back via Mutual TLS) | B12: Garante que apenas sessões legítimas permaneçam ativas, prevenindo uso indevido por terceiros. Protege contra ataques de sequestro de sessão (Session Hijacking). Deve incluir expiração automática e revalidação periódica. Implementação via tokens seguros, como JWT com assinatura. Essencial para manter integridade e segurança no acesso. | C12: Aplicação - Web/Mobile | D12: {=IF(Tabela1[[#This Row],[STRIDE LM]]="Information Disclosure",Formatação!H$5,IF(Tabela1[[#This Row],[STRIDE LM]]="Repudiation",Formatação!H$4,IF(Tabela1[[#This Row],[STRIDE LM]]="Spoofing",Formatação!H$2,IF(Tabela1[[#This Row],[STRIDE LM]]="Tampering",Formatação!H$3, IF(Tabela1[[#This Row],[STRIDE LM]]="Denial of Service",Formatação!H$6,IF(Tabela1[[#This Row],[STRIDE LM]]="Elevation of Privilege",Formatação!H$7,IF(Tabela1[[#This Row],[STRIDE LM]]="Lateral Movement",Formatação!H$8,Errado)))))))} -> Autorização | E12: Elevation of Privilege | F12: {=IF(Tabela1[[#This Row],[STRIDE LM]]="Information Disclosure",Formatação!J$5,IF(Tabela1[[#This Row],[STRIDE LM]]="Repudiation",Formatação!J$4,IF(Tabela1[[#This Row],[STRIDE LM]]="Spoofing",Formatação!J$2,IF(Tabela1[[#This Row],[STRIDE LM]]="Tampering",Formatação!J$3, IF(Tabela1[[#This Row],[STRIDE LM]]="Denial of Service",Formatação!J$6,IF(Tabela1[[#This Row],[STRIDE LM]]="Elevation of Privilege",Formatação!J$7,IF(Tabela1[[#This Row],[STRIDE LM]]="Lateral Movement",Formatação!J$8,Errado)))))))} -> Danos financeiros/Vazamento de dados | G12: A05:2021-Security Misconfiguration | J12: Sim | K12: Sim | L12: Sim | M12: Sim | N12: Utilizar criptografia fim a fim com Mutual TLS | O12: Implementar certificados TLS entre microsserviços e aplicar segmentação de rede com políticas Zero Trust.
A13: Os Bancos de Dados utilizados pela aplicação devem possuir uma rotina de backup documentada, aplicada e testada periodicamente | B13: Backups regulares são cruciais para a recuperação em caso de falhas ou ataques. A falta de backups bem geridos pode resultar em perda irreparável de dados críticos. | C13: Banco de Dados | D13: {=IF(Tabela1[[#This Row],[STRIDE LM]]="Information Disclosure",Formatação!H$5,IF(Tabela1[[#This Row],[STRIDE LM]]="Repudiation",Formatação!H$4,IF(Tabela1[[#This Row],[STRIDE LM]]="Spoofing",Formatação!H$2,IF(Tabela1[[#This Row],[STRIDE LM]]="Tampering",Formatação!H$3, IF(Tabela1[[#This Row],[STRIDE LM]]="Denial of Service",Formatação!H$6,IF(Tabela1[[#This Row],[STRIDE LM]]="Elevation of Privilege",Formatação!H$7,IF(Tabela1[[#This Row],[STRIDE LM]]="Lateral Movement",Formatação!H$8,Errado)))))))} -> Confidencialidade | E13: Information Disclosure | F13: {=IF(Tabela1[[#This Row],[STRIDE LM]]="Information Disclosure",Formatação!J$5,IF(Tabela1[[#This Row],[STRIDE LM]]="Repudiation",Formatação!J$4,IF(Tabela1[[#This Row],[STRIDE LM]]="Spoofing",Formatação!J$2,IF(Tabela1[[#This Row],[STRIDE LM]]="Tampering",Formatação!J$3, IF(Tabela1[[#This Row],[STRIDE LM]]="Denial of Service",Formatação!J$6,IF(Tabela1[[#This Row],[STRIDE LM]]="Elevation of Privilege",Formatação!J$7,IF(Tabela1[[#This Row],[STRIDE LM]]="Lateral Movement",Formatação!J$8,Errado)))))))} -> Vazamento de dados | G13: A04:2021-Insecure Design | J13: Sim | K13: Sim | L13: Sim | M13: Sim
A14: Toda e qualquer Fuction deverá estar exposta atrás de um API Gateway, além disso só poderá aceitar requisições externas das soluções de WAF definidas pela Companhia (ex: Akamai e/ou CloudFlare) | B14: O API Gateway controla e monitora o acesso a funções críticas da aplicação, limitando o risco de exploração externa. Sem isso, a aplicação fica vulnerável a abusos e ataques. | C14: Banco de dados | D14: {=IF(Tabela1[[#This Row],[STRIDE LM]]="Information Disclosure",Formatação!H$5,IF(Tabela1[[#This Row],[STRIDE LM]]="Repudiation",Formatação!H$4,IF(Tabela1[[#This Row],[STRIDE LM]]="Spoofing",Formatação!H$2,IF(Tabela1[[#This Row],[STRIDE LM]]="Tampering",Formatação!H$3, IF(Tabela1[[#This Row],[STRIDE LM]]="Denial of Service",Formatação!H$6,IF(Tabela1[[#This Row],[STRIDE LM]]="Elevation of Privilege",Formatação!H$7,IF(Tabela1[[#This Row],[STRIDE LM]]="Lateral Movement",Formatação!H$8,Errado)))))))} -> Integridade | E14: Tampering | F14: {=IF(Tabela1[[#This Row],[STRIDE LM]]="Information Disclosure",Formatação!J$5,IF(Tabela1[[#This Row],[STRIDE LM]]="Repudiation",Formatação!J$4,IF(Tabela1[[#This Row],[STRIDE LM]]="Spoofing",Formatação!J$2,IF(Tabela1[[#This Row],[STRIDE LM]]="Tampering",Formatação!J$3, IF(Tabela1[[#This Row],[STRIDE LM]]="Denial of Service",Formatação!J$6,IF(Tabela1[[#This Row],[STRIDE LM]]="Elevation of Privilege",Formatação!J$7,IF(Tabela1[[#This Row],[STRIDE LM]]="Lateral Movement",Formatação!J$8,Errado)))))))} -> Danos a imagem | G14: A03:2021-Injection | J14: Sim | K14: Sim | L14: Sim | M14: Sim | N14: Uso de prepared statements, sanitização de entrada e implementação de políticas CSP (Content Security Policy). | O14: Atualizar ORM para usar consultas parametrizadas; Configurar firewall de aplicações web (WAF) para bloquear payloads maliciosos.
A15: Implementar mecanismos para bloqueio de ataques de “Brute Force” (exemplo: CAPTCH) | B15: Mecanismos como CAPTCHA impedem tentativas automatizadas de adivinhar senhas. Sem essas medidas, a aplicação fica vulnerável a ataques de força bruta. | C15: Identidade e Acesso | D15: {=IF(Tabela1[[#This Row],[STRIDE LM]]="Information Disclosure",Formatação!H$5,IF(Tabela1[[#This Row],[STRIDE LM]]="Repudiation",Formatação!H$4,IF(Tabela1[[#This Row],[STRIDE LM]]="Spoofing",Formatação!H$2,IF(Tabela1[[#This Row],[STRIDE LM]]="Tampering",Formatação!H$3, IF(Tabela1[[#This Row],[STRIDE LM]]="Denial of Service",Formatação!H$6,IF(Tabela1[[#This Row],[STRIDE LM]]="Elevation of Privilege",Formatação!H$7,IF(Tabela1[[#This Row],[STRIDE LM]]="Lateral Movement",Formatação!H$8,Errado)))))))} -> Autorização | E15: Elevation of Privilege | F15: {=IF(Tabela1[[#This Row],[STRIDE LM]]="Information Disclosure",Formatação!J$5,IF(Tabela1[[#This Row],[STRIDE LM]]="Repudiation",Formatação!J$4,IF(Tabela1[[#This Row],[STRIDE LM]]="Spoofing",Formatação!J$2,IF(Tabela1[[#This Row],[STRIDE LM]]="Tampering",Formatação!J$3, IF(Tabela1[[#This Row],[STRIDE LM]]="Denial of Service",Formatação!J$6,IF(Tabela1[[#This Row],[STRIDE LM]]="Elevation of Privilege",Formatação!J$7,IF(Tabela1[[#This Row],[STRIDE LM]]="Lateral Movement",Formatação!J$8,Errado)))))))} -> Danos financeiros/Vazamento de dados | G15: A07:2021-Identification and Authentication Failures | J15: Sim | K15: Sim | L15: Sim | M15: Sim
A16: Garantir que cada token OTP (One Time Password), se aplicável, só possa ser usado uma única vez | B16: A utilização de tokens OTP únicos reduz o risco de replay attacks, onde tokens antigos podem ser reutilizados por atacantes. A falha nesse controle pode resultar em comprometimento de contas. | C16: Identidade e Acesso | D16: {=IF(Tabela1[[#This Row],[STRIDE LM]]="Information Disclosure",Formatação!H$5,IF(Tabela1[[#This Row],[STRIDE LM]]="Repudiation",Formatação!H$4,IF(Tabela1[[#This Row],[STRIDE LM]]="Spoofing",Formatação!H$2,IF(Tabela1[[#This Row],[STRIDE LM]]="Tampering",Formatação!H$3, IF(Tabela1[[#This Row],[STRIDE LM]]="Denial of Service",Formatação!H$6,IF(Tabela1[[#This Row],[STRIDE LM]]="Elevation of Privilege",Formatação!H$7,IF(Tabela1[[#This Row],[STRIDE LM]]="Lateral Movement",Formatação!H$8,Errado)))))))} -> Autorização | E16: Elevation of Privilege | F16: {=IF(Tabela1[[#This Row],[STRIDE LM]]="Information Disclosure",Formatação!J$5,IF(Tabela1[[#This Row],[STRIDE LM]]="Repudiation",Formatação!J$4,IF(Tabela1[[#This Row],[STRIDE LM]]="Spoofing",Formatação!J$2,IF(Tabela1[[#This Row],[STRIDE LM]]="Tampering",Formatação!J$3, IF(Tabela1[[#This Row],[STRIDE LM]]="Denial of Service",Formatação!J$6,IF(Tabela1[[#This Row],[STRIDE LM]]="Elevation of Privilege",Formatação!J$7,IF(Tabela1[[#This Row],[STRIDE LM]]="Lateral Movement",Formatação!J$8,Errado)))))))} -> Danos financeiros/Vazamento de dados | G16: A07:2021-Identification and Authentication Failures | J16: Sim | K16: Sim | L16: Sim | M16: Sim
A17: Solução obrigatoriamente precisa se integrar com o Identity Provider definido pela Companhia para autenticação e autorização atraves de modelos de segurança seguros como OpenID, Oauth2 e SAML2.0 no fluxo 3-Legged Authentication; | B17: A integração com o Identity Provider garante que os processos de autenticação e autorização sejam seguros e centralizados. | C17: Identidade e Acesso | D17: {=IF(Tabela1[[#This Row],[STRIDE LM]]="Information Disclosure",Formatação!H$5,IF(Tabela1[[#This Row],[STRIDE LM]]="Repudiation",Formatação!H$4,IF(Tabela1[[#This Row],[STRIDE LM]]="Spoofing",Formatação!H$2,IF(Tabela1[[#This Row],[STRIDE LM]]="Tampering",Formatação!H$3, IF(Tabela1[[#This Row],[STRIDE LM]]="Denial of Service",Formatação!H$6,IF(Tabela1[[#This Row],[STRIDE LM]]="Elevation of Privilege",Formatação!H$7,IF(Tabela1[[#This Row],[STRIDE LM]]="Lateral Movement",Formatação!H$8,Errado)))))))} -> Autenticação | E17: Spoofing | F17: {=IF(Tabela1[[#This Row],[STRIDE LM]]="Information Disclosure",Formatação!J$5,IF(Tabela1[[#This Row],[STRIDE LM]]="Repudiation",Formatação!J$4,IF(Tabela1[[#This Row],[STRIDE LM]]="Spoofing",Formatação!J$2,IF(Tabela1[[#This Row],[STRIDE LM]]="Tampering",Formatação!J$3, IF(Tabela1[[#This Row],[STRIDE LM]]="Denial of Service",Formatação!J$6,IF(Tabela1[[#This Row],[STRIDE LM]]="Elevation of Privilege",Formatação!J$7,IF(Tabela1[[#This Row],[STRIDE LM]]="Lateral Movement",Formatação!J$8,Errado)))))))} -> Fraudes/Vazamento de dados | G17: A01:2021-Broken Access Control | J17: Não | K17: Sim | L17: Sim | M17: Sim | N17: Implementar OAuth 2.0/OpenID, MFA, bloqueio de login após tentativas falhas e rate limiting. | O17: Configurar OpenID Connect no IAM; Aplicar regras de rate limiting no API Gateway; Monitorar tentativas de login suspeitas no SIEM.
A18: É mandatório que a solução suporte e implemente o modelo de autorização baseado em perfis de acesso conforme o padrão RBAC (Role Based Access Control) | B18: RBAC assegura que usuários tenham apenas os privilégios necessários para suas funções. A falta dessa implementação pode resultar em usuários com acesso indevido a recursos sensíveis. | C18: Identidade e Acesso | D18: {=IF(Tabela1[[#This Row],[STRIDE LM]]="Information Disclosure",Formatação!H$5,IF(Tabela1[[#This Row],[STRIDE LM]]="Repudiation",Formatação!H$4,IF(Tabela1[[#This Row],[STRIDE LM]]="Spoofing",Formatação!H$2,IF(Tabela1[[#This Row],[STRIDE LM]]="Tampering",Formatação!H$3, IF(Tabela1[[#This Row],[STRIDE LM]]="Denial of Service",Formatação!H$6,IF(Tabela1[[#This Row],[STRIDE LM]]="Elevation of Privilege",Formatação!H$7,IF(Tabela1[[#This Row],[STRIDE LM]]="Lateral Movement",Formatação!H$8,Errado)))))))} -> Autorização | E18: Elevation of Privilege | F18: {=IF(Tabela1[[#This Row],[STRIDE LM]]="Information Disclosure",Formatação!J$5,IF(Tabela1[[#This Row],[STRIDE LM]]="Repudiation",Formatação!J$4,IF(Tabela1[[#This Row],[STRIDE LM]]="Spoofing",Formatação!J$2,IF(Tabela1[[#This Row],[STRIDE LM]]="Tampering",Formatação!J$3, IF(Tabela1[[#This Row],[STRIDE LM]]="Denial of Service",Formatação!J$6,IF(Tabela1[[#This Row],[STRIDE LM]]="Elevation of Privilege",Formatação!J$7,IF(Tabela1[[#This Row],[STRIDE LM]]="Lateral Movement",Formatação!J$8,Errado)))))))} -> Danos financeiros/Vazamento de dados | G18: A01:2021-Broken Access Control | J18: Sim | K18: Sim | L18: Sim | M18: Sim | N18: Implementar RBAC/ABAC, aplicar o princípio do menor privilégio e realizar auditoria de permissões periodicamente. | O18: "Configurar IAM para separar funções administrativas e operacionais; Implementar auditoria contínua de acessos."
A19: Utilize assinaturas digitais para garantir a autenticidade e a origem das mensagens, permitindo que a fonte seja verificada de forma irrefutável. | B19: As assinaturas digitais garantem que as mensagens ou transações sejam autênticas, vindas de uma fonte verificada, e não modificadas em trânsito. Isso é fundamental para evitar falsificação de dados e garantir a integridade das informações. A não utilização dessas assinaturas pode permitir ataques como spoofing e falsificação de identidade. | C19: Serverless & Functions | D19: {=IF(Tabela1[[#This Row],[STRIDE LM]]="Information Disclosure",Formatação!H$5,IF(Tabela1[[#This Row],[STRIDE LM]]="Repudiation",Formatação!H$4,IF(Tabela1[[#This Row],[STRIDE LM]]="Spoofing",Formatação!H$2,IF(Tabela1[[#This Row],[STRIDE LM]]="Tampering",Formatação!H$3, IF(Tabela1[[#This Row],[STRIDE LM]]="Denial of Service",Formatação!H$6,IF(Tabela1[[#This Row],[STRIDE LM]]="Elevation of Privilege",Formatação!H$7,IF(Tabela1[[#This Row],[STRIDE LM]]="Lateral Movement",Formatação!H$8,Errado)))))))} -> Contenção | E19: Lateral Movement | F19: {=IF(Tabela1[[#This Row],[STRIDE LM]]="Information Disclosure",Formatação!J$5,IF(Tabela1[[#This Row],[STRIDE LM]]="Repudiation",Formatação!J$4,IF(Tabela1[[#This Row],[STRIDE LM]]="Spoofing",Formatação!J$2,IF(Tabela1[[#This Row],[STRIDE LM]]="Tampering",Formatação!J$3, IF(Tabela1[[#This Row],[STRIDE LM]]="Denial of Service",Formatação!J$6,IF(Tabela1[[#This Row],[STRIDE LM]]="Elevation of Privilege",Formatação!J$7,IF(Tabela1[[#This Row],[STRIDE LM]]="Lateral Movement",Formatação!J$8,Errado)))))))} -> Vazamento de dados | G19: A08:2021-Software and Data Integrity Failures | J19: Sim | K19: Sim | L19: Sim | M19: Sim
A20: Provisionar soluções de antivírus e monitoramento de endpoints (EDR). Toda maquina de sistema operação | B20: A implementação de soluções de antivírus e EDR (Endpoint Detection and Response) em todas as máquinas de sistema operacional ajuda a detectar, bloquear e responder a ameaças em tempo real. Sem essas soluções, os endpoints ficam vulneráveis a malware, ransomware e outros tipos de ataques que podem comprometer a integridade do sistema. | C20: Workstation | D20: {=IF(Tabela1[[#This Row],[STRIDE LM]]="Information Disclosure",Formatação!H$5,IF(Tabela1[[#This Row],[STRIDE LM]]="Repudiation",Formatação!H$4,IF(Tabela1[[#This Row],[STRIDE LM]]="Spoofing",Formatação!H$2,IF(Tabela1[[#This Row],[STRIDE LM]]="Tampering",Formatação!H$3, IF(Tabela1[[#This Row],[STRIDE LM]]="Denial of Service",Formatação!H$6,IF(Tabela1[[#This Row],[STRIDE LM]]="Elevation of Privilege",Formatação!H$7,IF(Tabela1[[#This Row],[STRIDE LM]]="Lateral Movement",Formatação!H$8,Errado)))))))} -> Integridade | E20: Tampering | F20: {=IF(Tabela1[[#This Row],[STRIDE LM]]="Information Disclosure",Formatação!J$5,IF(Tabela1[[#This Row],[STRIDE LM]]="Repudiation",Formatação!J$4,IF(Tabela1[[#This Row],[STRIDE LM]]="Spoofing",Formatação!J$2,IF(Tabela1[[#This Row],[STRIDE LM]]="Tampering",Formatação!J$3, IF(Tabela1[[#This Row],[STRIDE LM]]="Denial of Service",Formatação!J$6,IF(Tabela1[[#This Row],[STRIDE LM]]="Elevation of Privilege",Formatação!J$7,IF(Tabela1[[#This Row],[STRIDE LM]]="Lateral Movement",Formatação!J$8,Errado)))))))} -> Danos a imagem | G20: A08:2021-Software and Data Integrity Failures | J20: Sim | K20: Sim | L20: Não | M20: Não
A21: É necessário manter o software e as dependências atualizados, aplicando correções de segurança regularmente para mitigar as vulnerabilidades conhecidas. | B21: Manter o software e suas dependências atualizados reduz a exposição a vulnerabilidades conhecidas. Aplicar patches de segurança de forma constante impede que falhas de segurança sejam exploradas. A não atualização pode resultar em sistemas obsoletos que são facilmente comprometidos por atacantes utilizando exploits já conhecidos. | C21: Workstation | D21: {=IF(Tabela1[[#This Row],[STRIDE LM]]="Information Disclosure",Formatação!H$5,IF(Tabela1[[#This Row],[STRIDE LM]]="Repudiation",Formatação!H$4,IF(Tabela1[[#This Row],[STRIDE LM]]="Spoofing",Formatação!H$2,IF(Tabela1[[#This Row],[STRIDE LM]]="Tampering",Formatação!H$3, IF(Tabela1[[#This Row],[STRIDE LM]]="Denial of Service",Formatação!H$6,IF(Tabela1[[#This Row],[STRIDE LM]]="Elevation of Privilege",Formatação!H$7,IF(Tabela1[[#This Row],[STRIDE LM]]="Lateral Movement",Formatação!H$8,Errado)))))))} -> Integridade | E21: Tampering | F21: {=IF(Tabela1[[#This Row],[STRIDE LM]]="Information Disclosure",Formatação!J$5,IF(Tabela1[[#This Row],[STRIDE LM]]="Repudiation",Formatação!J$4,IF(Tabela1[[#This Row],[STRIDE LM]]="Spoofing",Formatação!J$2,IF(Tabela1[[#This Row],[STRIDE LM]]="Tampering",Formatação!J$3, IF(Tabela1[[#This Row],[STRIDE LM]]="Denial of Service",Formatação!J$6,IF(Tabela1[[#This Row],[STRIDE LM]]="Elevation of Privilege",Formatação!J$7,IF(Tabela1[[#This Row],[STRIDE LM]]="Lateral Movement",Formatação!J$8,Errado)))))))} -> Danos a imagem | G21: A05:2021-Security Misconfiguration | J21: Sim | K21: Sim | L21: Sim | M21: Não
A22: Implementar mecanismos para bloqueio de ataques de “Brute Force” (exemplo: CAPTCH) | B22: Mecanismos como CAPTCHAs protegem contra ataques de força bruta, nos quais os atacantes tentam diversas combinações de senhas para acessar sistemas. A implementação de CAPTCHAs ou outras formas de bloqueio, como limites de tentativas, é crucial para garantir a segurança contra esse tipo de ataque. A falta dessa proteção pode permitir que atacantes consigam comprometer contas facilmente por meio de tentativa e erro. | C22: Workstation | D22: {=IF(Tabela1[[#This Row],[STRIDE LM]]="Information Disclosure",Formatação!H$5,IF(Tabela1[[#This Row],[STRIDE LM]]="Repudiation",Formatação!H$4,IF(Tabela1[[#This Row],[STRIDE LM]]="Spoofing",Formatação!H$2,IF(Tabela1[[#This Row],[STRIDE LM]]="Tampering",Formatação!H$3, IF(Tabela1[[#This Row],[STRIDE LM]]="Denial of Service",Formatação!H$6,IF(Tabela1[[#This Row],[STRIDE LM]]="Elevation of Privilege",Formatação!H$7,IF(Tabela1[[#This Row],[STRIDE LM]]="Lateral Movement",Formatação!H$8,Errado)))))))} -> Autorização | E22: Elevation of Privilege | F22: {=IF(Tabela1[[#This Row],[STRIDE LM]]="Information Disclosure",Formatação!J$5,IF(Tabela1[[#This Row],[STRIDE LM]]="Repudiation",Formatação!J$4,IF(Tabela1[[#This Row],[STRIDE LM]]="Spoofing",Formatação!J$2,IF(Tabela1[[#This Row],[STRIDE LM]]="Tampering",Formatação!J$3, IF(Tabela1[[#This Row],[STRIDE LM]]="Denial of Service",Formatação!J$6,IF(Tabela1[[#This Row],[STRIDE LM]]="Elevation of Privilege",Formatação!J$7,IF(Tabela1[[#This Row],[STRIDE LM]]="Lateral Movement",Formatação!J$8,Errado)))))))} -> Danos financeiros/Vazamento de dados | G22: A07:2021-Identification and Authentication Failures | J22: Sim | K22: Sim | L22: Sim | M22: Sim
